{
  "cve": {
    "data_type": "CVE",
    "data_format": "MITRE",
    "data_version": "4.0",
    "CVE_data_meta": {
      "ID": "CVE-2015-3206",
      "ASSIGNER": "secalert@redhat.com"
    },
    "problemtype": {
      "problemtype_data": [
        {
          "description": [
            {
              "lang": "en",
              "value": "CWE-287"
            }
          ]
        }
      ]
    },
    "references": {
      "reference_data": [
        {
          "url": "https://pypi.python.org/pypi/kerberos",
          "name": "https://pypi.python.org/pypi/kerberos",
          "refsource": "CONFIRM",
          "tags": [
            "Patch",
            "Vendor Advisory"
          ]
        },
        {
          "url": "https://github.com/apple/ccs-pykerberos/issues/31",
          "name": "https://github.com/apple/ccs-pykerberos/issues/31",
          "refsource": "CONFIRM",
          "tags": [
            "Issue Tracking",
            "Patch",
            "Third Party Advisory"
          ]
        },
        {
          "url": "https://bugzilla.redhat.com/show_bug.cgi?id=1223802",
          "name": "https://bugzilla.redhat.com/show_bug.cgi?id=1223802",
          "refsource": "CONFIRM",
          "tags": [
            "Issue Tracking",
            "Patch",
            "Third Party Advisory"
          ]
        },
        {
          "url": "http://www.securityfocus.com/bid/74760",
          "name": "74760",
          "refsource": "BID",
          "tags": [
            "Third Party Advisory",
            "VDB Entry"
          ]
        },
        {
          "url": "http://www.openwall.com/lists/oss-security/2015/05/21/3",
          "name": "[oss-security] 20150521 CVE-2015-3206 python-kerberos: checkPassword() does not verify KDC authenticity",
          "refsource": "MLIST",
          "tags": [
            "Mailing List",
            "Patch",
            "Third Party Advisory"
          ]
        }
      ]
    },
    "description": {
      "description_data": [
        {
          "lang": "en",
          "value": "The checkPassword function in python-kerberos does not authenticate the KDC it attempts to communicate with, which allows remote attackers to cause a denial of service (bad response), or have other unspecified impact by performing a man-in-the-middle attack."
        }
      ]
    }
  },
  "configurations": {
    "nodes": [
      {
        "operator": "OR",
        "cpe_match": [
          {
            "vulnerable": true,
            "cpe23Uri": "cpe:2.3:a:apple:pykerberos:-:*:*:*:*:*:*:*"
          }
        ]
      }
    ]
  },
  "impact": {
    "baseMetricV2": {
      "cvssV2": {
        "vectorString": "AV:N/AC:M/Au:N/C:P/I:P/A:P",
        "accessVector": "NETWORK",
        "accessComplexity": "MEDIUM",
        "authentication": "NONE",
        "confidentialityImpact": "PARTIAL",
        "integrityImpact": "PARTIAL",
        "availabilityImpact": "PARTIAL",
        "baseScore": 6.8
      },
      "severity": "MEDIUM",
      "exploitabilityScore": 8.6,
      "impactScore": 6.4,
      "obtainAllPrivilege": false,
      "obtainUserPrivilege": false,
      "obtainOtherPrivilege": false,
      "userInteractionRequired": false
    }
  },
  "publishedDate": "2017-08-25T18:29Z",
  "lastModifiedDate": "2018-12-20T18:11Z"
}